Workbook
Name Slicer_Channel: #N/A
Name Slicer_Country: #N/A
Name Slicer_Order_Date__Month: #N/A
Name Slicer_ProductCategory: #N/A
Name Slicer_ProductCategory1: #N/A
Name Slicer_ProductCategory2: #N/A
Name Slicer_ProductCategory3: #N/A
Name Slicer_Quarters: #N/A
Name Slicer_Region: #N/A
Name Slicer_Region1: #N/A
Name Slicer_Region2: #N/A
Name Slicer_Salesperson: #N/A
Name Slicer_Salesperson1: #N/A
Name Slicer_Salesperson2: #N/A
Name Slicer_SKU: #N/A

Sheet Brief
A1: Assignment
A2: Excel Mastery Assignment: Sales Operations & Analytics
A4: Overview:
A5: You are an analyst for a multi-regional electronics distributor. The 'Data' sheet contains 632 rows and 15 columns of transactional data with intentional data-quality issues.
A6: Your job is to clean, enrich, analyze, and present insights via a dynamic dashboard.
A8: Part A — Data Cleaning & Preparation:
A9: 1) Create a staging table where you:
A10: • Remove exact duplicate rows (define and document your duplicate criteria).
A11: • Fix data types (dates as Dates, numeric fields as numbers).
A12: • Handle missing values for City, Salesperson, and Channel using reasonable business logic (document your approach).
A13: • Flag and correct suspicious UnitPrice values (e.g., negative prices) and discounts (e.g., > 30%).
A14: • Ensure RequiredDate is not earlier than OrderDate; where it is, impute a corrected RequiredDate (explain your rule).
... A67: 15) Ensure your dashboard responds to slicers without broken references.

Sheet Data
A1: OrderID | B1: OrderDate | C1: RequiredDate | D1: Region | E1: Country | F1: City | G1: CustomerSegment | H1: Channel | I1: Salesperson | J1: ProductCategory | K1: SKU | L1: UnitCost | M1: UnitPrice | N1: DiscountPct | O1: Quantity
A2: ORD-2024-275203 | B2: 45362 | C2: 45388 | D2: Africa | E2: Kenya | F2: Kisumu | G2: Corporate | H2: Retail | I2: C. Otieno | J2: Components | K2: CMP-8270 | L2: 279.24 | M2: 608.9 | N2: 0.112 | O2: 9
A3: ORD-2024-358795 | B3: 45588 | C3: 45587 | D3: Africa | E3: Nigeria | F3: Port Harcourt | G3: Education | H3: Online | I3: J. Njeri | J3: Printers | K3: PRN-9322 | L3: 1084.39 | M3: 759.33 | N3: 0.237 | O3: 31
A4: ORD-2023-373538 | B4: 44985 | C4: 45010 | D4: Africa | E4: Kenya | F4: Nairobi | G4: Corporate | H4: Retail | I4: I. Johnson | J4: Networking | K4: NET-9666 | L4: 1460.76 | M4: -30.66 | N4: 0.131 | O4: 12
A5: ORD-2025-168148 | B5: 45745 | C5: 45749 | D5: Africa | E5: Nigeria | F5: Lagos | G5: Non-Profit | H5: Marketplace | I5: G. Dubois | J5: Phones | K5: PHN-4556 | L5: 259.93 | M5: 255.94 | N5: 0.072 | O5: 22
A6: ORD-2023-824839 | B6: 45266 | C6: 45291 | D6: Asia | E6: Japan | F6: Osaka | G6: Consumer | H6: Retail | I6: L. Okafor | J6: Printers | K6: PRN-8041 | L6: 663.03 | M6: 813.51 | N6: 0.102 | O6: 15
A7: ORD-2023-723587 | B7: 44928 | C7: 44931 | D7: Americas | E7: Canada | F7: Toronto | G7: Corporate | H7: Distributor | I7: B. Chen | J7: Laptops | K7: LAP-8555 | L7: 315.87 | M7: 591.68 | N7: 0 | O7: 7
A8: ORD-2024-336584 | B8: 45653 | C8: 45671 | D8: Asia | E8: India | F8: Bengaluru | G8: Small Business | H8: Marketplace | I8: E. Garcia | J8: Monitors | K8: MON-8629 | L8: 586.07 | M8: 845.97 | N8: 0.147 | O8: 4
A9: ORD-2023-112666 | B9: 44941 | C9: 44939 | D9: Africa | E9: Nigeria | F9: Abuja | G9: Education | H9: Online | I9: O. Wang | J9: Printers | K9: PRN-6276 | L9: 28.38 | M9: 47.22 | N9: 0.194 | O9: 18
A10: ORD-2024-589570 | B10: 45416 | C10: 45441 | D10: Africa | E10: Nigeria | F10: Abuja | G10: Non-Profit | H10: Marketplace | I10: O. Wang | J10: Monitors | K10: MON-6892 | L10: 1295.34 | M10: 2530.81 | N10: 0.031 | O10: 6
A11: ORD-2025-997421 | B11: 45798 | C11: 45817 | D11: Americas | E11: Brazil | F11: São Paulo | G11: Non-Profit | H11: Online | I11: A. Patel | J11: Components | K11: CMP-3731 | L11: 1331.38 | M11: 2309.56 | N11: 0.149 | O11: 31
A12: ORD-2024-210687 | B12: 45319 | C12: 45331 | D12: Europe | E12: Germany | F12: Berlin | G12: Corporate | H12: Online | I12: G. Dubois | J12: Accessories | K12: ACC-7938 | L12: 644.17 | M12: 700.12 | N12: 0.006 | O12: 23
A13: ORD-2025-515515 | B13: 45660 | C13: 45680 | D13: Asia | E13: Japan | F13: Osaka | G13: Corporate | H13: Distributor | I13: F. Müller | J13: Phones | K13: PHN-7019 | L13: 908.6 | M13: 691.37 | N13: 0.25 | O13: 20
... A34: ORD-2025-474710 | B34: 45862 | C34: 45875 | D34: Africa | E34: South Africa | F34: Johannesburg | G34: Education | H34: Marketplace | I34: D. Smith | J34: Networking | K34: NET-7966 | L34: 1463.9 | M34: 2633.02 | N34: 0.084 | O34: 4
A35: ORD-2024-629525 | B35: 45400 | C35: 45420 | D35: Europe | E35: United Kingdom | F35: London | G35: Non-Profit | I35: D. Smith | J35: Laptops | K35: LAP-9932 | L35: 645.33 | M35: 1321.85 | N35: 0 | O35: 10
A36: ORD-2024-167215 | B36: 45527 | C36: 45525 | D36: Africa | E36: South Africa | F36: Johannesburg | G36: Education | H36: Retail | I36: E. Garcia | J36: Components | K36: CMP-1559 | L36: 1432.52 | M36: 3036.87 | N36: 0 | O36: 9
A37: ORD-2023-864121 | B37: 45012 | C37: 45038 | D37: Asia | E37: India | F37: Delhi | G37: Non-Profit | H37: Marketplace | I37: J. Njeri | J37: Printers | K37: PRN-4506 | L37: 178.53 | M37: 199.37 | N37: 0.101 | O37: 37
A38: ORD-2024-692673 | B38: 45358 | C38: 45376 | D38: Europe | E38: Germany | F38: Munich | G38: Corporate | H38: Online | I38: B. Chen | J38: Components | K38: CMP-7617 | L38: 712.84 | M38: 927.51 | N38: 0.243 | O38: 27
A39: ORD-2025-718992 | B39: 45832 | C39: 45848 | D39: Asia | E39: China | F39: Shanghai | G39: Enterprise | H39: Direct | I39: N. Brown | J39: Components | K39: CMP-8390 | L39: 757.19 | M39: 1735.41 | N39: 0.136 | O39: 8
A40: ORD-2024-599522 | B40: 45401 | C40: 45418 | D40: Africa | E40: Nigeria | F40: Port Harcourt | G40: Non-Profit | H40: Online | I40: A. Patel | J40: Printers | K40: PRN-7303 | L40: 865.33 | M40: 1395.64 | N40: 0.175 | O40: 13
A41: ORD-2023-651638 | B41: 45094 | C41: 45101 | D41: Americas | E41: USA | F41: San Francisco | G41: Corporate | H41: Retail | I41: I. Johnson | J41: Printers | K41: PRN-6536 | L41: 313.99 | M41: 454.42 | N41: 0.129 | O41: 9
A42: ORD-2024-635626 | B42: 45531 | C42: 45554 | D42: Europe | E42: Germany | F42: Berlin | G42: Small Business | H42: Direct | I42: D. Smith | J42: Monitors | K42: MON-9967 | L42: 1024.01 | M42: 1580.97 | N42: 0.037 | O42: 27
A43: ORD-2024-296582 | B43: 45302 | C43: 45324 | D43: Africa | E43: South Africa | F43: Durban | G43: Consumer | H43: Online | I43: K. Singh | J43: Networking | K43: NET-1412 | L43: 1206.2 | M43: 1759.79 | N43: 0 | O43: 6
A44: ORD-2024-998320 | B44: 45590 | C44: 45610 | D44: Africa | E44: Kenya | F44: Mombasa | G44: Corporate | H44: Direct | I44: H. Kim | J44: Printers | K44: PRN-3143 | L44: 1396.48 | M44: 3204.5 | N44: 0.318 | O44: 14
A45: ORD-2025-820255 | B45: 45806 | C45: 45828 | D45: Europe | E45: Germany | F45: Berlin | G45: Corporate | H45: Direct | I45: A. Patel | J45: Printers | K45: PRN-9787 | L45: 483.47 | M45: 1135.43 | N45: 0.146 | O45: 11
A46: ORD-2024-389336 | B46: 45432 | C46: 45445 | D46: Americas | E46: Canada | F46: Vancouver | G46: Enterprise | H46: Marketplace | I46: K. Singh | J46: Components | K46: CMP-5946 | L46: 675.43 | M46: 996.36 | N46: 0.182 | O46: 22
A47: ORD-2023-308124 | B47: 45035 | C47: 45046 | D47: Asia | E47: India | F47: Delhi | G47: Small Business | H47: Retail | I47: A. Patel | J47: Networking | K47: NET-2062 | L47: 826.55 | M47: 1397.05 | N47: 0.169 | O47: 28
... A77: ORD-2023-722117 | B77: 45187 | C77: 45207 | D77: Asia | E77: India | F77: Delhi | G77: Small Business | H77: Direct | I77: B. Chen | J77: Components | K77: CMP-1009 | L77: 825.64 | M77: 1108.43 | N77: 0.114 | O77: 7
A78: ORD-2024-446699 | B78: 45532 | C78: 45560 | D78: Americas | E78: Brazil | F78: Rio de Janeiro | G78: Non-Profit | H78: Online | J78: Accessories | K78: ACC-4490 | L78: 1394.65 | M78: 3144.1 | N78: 0.134 | O78: 13
A79: ORD-2024-451005 | B79: 45473 | C79: 45471 | D79: Americas | E79: Brazil | F79: Rio de Janeiro | G79: Small Business | H79: Direct | I79: L. Okafor | J79: Accessories | K79: ACC-9162 | L79: 1112.98 | M79: 2095.73 | N79: 0.072 | O79: 17
A80: ORD-2023-290279 | B80: 45091 | C80: 45093 | D80: Europe | E80: United Kingdom | F80: Manchester | G80: Non-Profit | H80: Direct | I80: K. Singh | J80: Components | K80: CMP-5820 | L80: 357.36 | M80: 703.62 | N80: 0.257 | O80: 20
A81: ORD-2024-192263 | B81: 45617 | C81: 45647 | D81: Europe | E81: France | F81: Marseille | G81: Small Business | H81: Direct | I81: I. Johnson | J81: Monitors | K81: MON-7943 | L81: 1122.68 | M81: 1997.19 | N81: 0.186 | O81: 3
A82: ORD-2023-159379 | B82: 44965 | C82: 44968 | D82: Africa | E82: South Africa | F82: Cape Town | G82: Corporate | H82: Direct | I82: M. Rossi | J82: Networking | K82: NET-5018 | L82: 1410.05 | M82: 2763.95 | N82: 0.161 | O82: 26
A83: ORD-2023-343322 | B83: 45157 | C83: 45181 | D83: Americas | E83: Canada | F83: Vancouver | G83: Enterprise | H83: Retail | I83: I. Johnson | J83: Printers | K83: PRN-9669 | L83: 1183.95 | M83: 1503.53 | N83: 0.241 | O83: 16
A84: ORD-2025-114382 | B84: 45791 | C84: 45801 | D84: Europe | E84: France | F84: Paris | G84: Small Business | H84: Marketplace | I84: K. Singh | J84: Components | K84: CMP-2865 | L84: 170.39 | M84: 388.04 | N84: 0.084 | O84: 15
A85: ORD-2025-488349 | B85: 45770 | C85: 45769 | D85: Americas | E85: USA | F85: San Francisco | G85: Non-Profit | H85: Distributor | I85: D. Smith | J85: Monitors | K85: MON-3371 | L85: 23.24 | M85: 44.57 | N85: 0.215 | O85: 15
A86: ORD-2025-330203 | B86: 45741 | C86: 45764 | D86: Europe | E86: United Kingdom | F86: London | G86: Consumer | H86: Retail | I86: H. Kim | J86: Networking | K86: NET-7166 | L86: 1421.19 | M86: 1808.26 | N86: 0.104 | O86: 13
A87: ORD-2023-841426 | B87: 45282 | C87: 45283 | D87: Africa | E87: South Africa | F87: Cape Town | G87: Non-Profit | H87: Marketplace | I87: D. Smith | J87: Components | K87: CMP-4531 | L87: 1186.18 | M87: 1285.09 | N87: 0.07 | O87: 11
A88: ORD-2024-594592 | B88: 45388 | C88: 45407 | D88: Asia | E88: China | F88: Shanghai | G88: Corporate | H88: Retail | I88: K. Singh | J88: Components | K88: CMP-8196 | L88: 1366.48 | M88: 1678.14 | N88: 0.154 | O88: 10
A89: ORD-2025-863978 | B89: 45876 | C89: 45888 | D89: Africa | E89: Kenya | F89: Nakuru | G89: Corporate | I89: M. Rossi | J89: Components | K89: CMP-2854 | L89: 601.51 | M89: 679.35 | N89: 0.188 | O89: 3
...

Sheet staging table
A1: cc | B1: Order Date | C1: Required Date | D1: Quarter 1 | E1: Lead time date | F1: Region | G1: Country | H1: City | I1: Customer Segment | J1: Channel | K1: Salesperson | L1: ProductCategory | M1: Price Brand | N1: SKU | O1: UnitCost | P1: UnitPrice | Q1: DiscountPct | R1: Quantity
A2: ORD-2024-275203 | B2: 45362 | C2: 45388 | D2: =IF(AND(MONTH(B2)>=1,MONTH(B2)<=3),"QUARTER 1",IF(AND(MONTH(B2)>=4,MONTH(B2)<=6),"QUARTER 2",IF(AND(MONTH(B2)>=7,MONTH(B2)<=9),"QUARTER 3",IF(AND(MONTH(B2)>=10,MONTH(B2)<=12),"QUARTER 4")))) -> QUARTER 1 | E2: =(C2-B2) -> 26 | F2: Africa | G2: Kenya | H2: Kisumu | I2: Corporate | J2: Retail | K2: C. Otieno | L2: Components | N2: CMP-8270 | O2: 279.24 | P2: 608.9 | Q2: 0.112 | R2: 9
A3: ORD-2024-358795 | B3: 45587 | C3: 45588 | D3: =IF(AND(MONTH(B3)>=1,MONTH(B3)<=3),"QUARTER 1",IF(AND(MONTH(B3)>=4,MONTH(B3)<=6),"QUARTER 2",IF(AND(MONTH(B3)>=7,MONTH(B3)<=9),"QUARTER 3",IF(AND(MONTH(B3)>=10,MONTH(B3)<=12),"QUARTER 4")))) -> QUARTER 4 | E3: =(C3-B3) -> 1 | F3: Africa | G3: Nigeria | H3: Port Harcourt | I3: Education | J3: Online | K3: J. Njeri | L3: Printers | N3: PRN-9322 | O3: 1084.39 | P3: 759.33 | Q3: 0.237 | R3: 31
A4: ORD-2023-373538 | B4: 44985 | C4: 45010 | D4: =IF(AND(MONTH(B4)>=1,MONTH(B4)<=3),"QUARTER 1",IF(AND(MONTH(B4)>=4,MONTH(B4)<=6),"QUARTER 2",IF(AND(MONTH(B4)>=7,MONTH(B4)<=9),"QUARTER 3",IF(AND(MONTH(B4)>=10,MONTH(B4)<=12),"QUARTER 4")))) -> QUARTER 1 | E4: =(C4-B4) -> 25 | F4: Africa | G4: Kenya | H4: Nairobi | I4: Corporate | J4: Retail | K4: I. Johnson | L4: Networking | N4: NET-9666 | O4: 1460.76 | P4: -30.66 | Q4: 0.131 | R4: 12
A5: ORD-2025-168148 | B5: 45745 | C5: 45749 | D5: =IF(AND(MONTH(B5)>=1,MONTH(B5)<=3),"QUARTER 1",IF(AND(MONTH(B5)>=4,MONTH(B5)<=6),"QUARTER 2",IF(AND(MONTH(B5)>=7,MONTH(B5)<=9),"QUARTER 3",IF(AND(MONTH(B5)>=10,MONTH(B5)<=12),"QUARTER 4")))) -> QUARTER 1 | E5: =(C5-B5) -> 4 | F5: Africa | G5: Nigeria | H5: Lagos | I5: Non-Profit | J5: Marketplace | K5: G. Dubois | L5: Phones | N5: PHN-4556 | O5: 259.93 | P5: 255.94 | Q5: 0.072 | R5: 22
A6: ORD-2023-824839 | B6: 45266 | C6: 45291 | D6: =IF(AND(MONTH(B6)>=1,MONTH(B6)<=3),"QUARTER 1",IF(AND(MONTH(B6)>=4,MONTH(B6)<=6),"QUARTER 2",IF(AND(MONTH(B6)>=7,MONTH(B6)<=9),"QUARTER 3",IF(AND(MONTH(B6)>=10,MONTH(B6)<=12),"QUARTER 4")))) -> QUARTER 4 | E6: =(C6-B6) -> 25 | F6: Asia | G6: Japan | H6: Osaka | I6: Consumer | J6: Retail | K6: L. Okafor | L6: Printers | N6: PRN-8041 | O6: 663.03 | P6: 813.51 | Q6: 0.102 | R6: 15
A7: ORD-2023-723587 | B7: 44928 | C7: 44931 | D7: =IF(AND(MONTH(B7)>=1,MONTH(B7)<=3),"QUARTER 1",IF(AND(MONTH(B7)>=4,MONTH(B7)<=6),"QUARTER 2",IF(AND(MONTH(B7)>=7,MONTH(B7)<=9),"QUARTER 3",IF(AND(MONTH(B7)>=10,MONTH(B7)<=12),"QUARTER 4")))) -> QUARTER 1 | E7: =(C7-B7) -> 3 | F7: Americas | G7: Canada | H7: Toronto | I7: Corporate | J7: Distributor | K7: B. Chen | L7: Laptops | N7: Not Provided | O7: 315.87 | P7: 591.68 | Q7: 0 | R7: 7
A8: ORD-2024-336584 | B8: 45653 | C8: 45671 | D8: =IF(AND(MONTH(B8)>=1,MONTH(B8)<=3),"QUARTER 1",IF(AND(MONTH(B8)>=4,MONTH(B8)<=6),"QUARTER 2",IF(AND(MONTH(B8)>=7,MONTH(B8)<=9),"QUARTER 3",IF(AND(MONTH(B8)>=10,MONTH(B8)<=12),"QUARTER 4")))) -> QUARTER 4 | E8: =(C8-B8) -> 18 | F8: Asia | G8: India | H8: Bengaluru | I8: Small Business | J8: Marketplace | K8: E. Garcia | L8: Monitors | N8: MON-8629 | O8: 586.07 | P8: 845.97 | Q8: 0.147 | R8: 4
A9: ORD-2023-112666 | B9: 44939 | C9: 44941 | D9: =IF(AND(MONTH(B9)>=1,MONTH(B9)<=3),"QUARTER 1",IF(AND(MONTH(B9)>=4,MONTH(B9)<=6),"QUARTER 2",IF(AND(MONTH(B9)>=7,MONTH(B9)<=9),"QUARTER 3",IF(AND(MONTH(B9)>=10,MONTH(B9)<=12),"QUARTER 4")))) -> QUARTER 1 | E9: =(C9-B9) -> 2 | F9: Africa | G9: Nigeria | H9: Abuja | I9: Education | J9: Online | K9: O. Wang | L9: Printers | N9: PRN-6276 | O9: 28.38 | P9: 47.22 | Q9: 0.194 | R9: 18
A10: ORD-2024-589570 | B10: 45416 | C10: 45441 | D10: =IF(AND(MONTH(B10)>=1,MONTH(B10)<=3),"QUARTER 1",IF(AND(MONTH(B10)>=4,MONTH(B10)<=6),"QUARTER 2",IF(AND(MONTH(B10)>=7,MONTH(B10)<=9),"QUARTER 3",IF(AND(MONTH(B10)>=10,MONTH(B10)<=12),"QUARTER 4")))) -> QUARTER 2 | E10: =(C10-B10) -> 25 | F10: Africa | G10: Nigeria | H10: Abuja | I10: Non-Profit | J10: Marketplace | K10: O. Wang | L10: Monitors | N10: MON-6892 | O10: 1295.34 | P10: 2530.81 | Q10: 0.031 | R10: 6
A11: ORD-2025-997421 | B11: 45798 | C11: 45817 | D11: =IF(AND(MONTH(B11)>=1,MONTH(B11)<=3),"QUARTER 1",IF(AND(MONTH(B11)>=4,MONTH(B11)<=6),"QUARTER 2",IF(AND(MONTH(B11)>=7,MONTH(B11)<=9),"QUARTER 3",IF(AND(MONTH(B11)>=10,MONTH(B11)<=12),"QUARTER 4")))) -> QUARTER 2 | E11: =(C11-B11) -> 19 | F11: Americas | G11: Brazil | H11: São Paulo | I11: Non-Profit | J11: Online | K11: A. Patel | L11: Components | N11: CMP-3731 | O11: 1331.38 | P11: 2309.56 | Q11: 0.149 | R11: 31
A12: ORD-2024-210687 | B12: 45319 | C12: 45331 | D12: =IF(AND(MONTH(B12)>=1,MONTH(B12)<=3),"QUARTER 1",IF(AND(MONTH(B12)>=4,MONTH(B12)<=6),"QUARTER 2",IF(AND(MONTH(B12)>=7,MONTH(B12)<=9),"QUARTER 3",IF(AND(MONTH(B12)>=10,MONTH(B12)<=12),"QUARTER 4")))) -> QUARTER 1 | E12: =(C12-B12) -> 12 | F12: Europe | G12: Germany | H12: Berlin | I12: Corporate | J12: Online | K12: G. Dubois | L12: Accessories | N12: ACC-7938 | O12: 644.17 | P12: 700.12 | Q12: 0.006 | R12: 23
A13: ORD-2025-515515 | B13: 45660 | C13: 45680 | D13: =IF(AND(MONTH(B13)>=1,MONTH(B13)<=3),"QUARTER 1",IF(AND(MONTH(B13)>=4,MONTH(B13)<=6),"QUARTER 2",IF(AND(MONTH(B13)>=7,MONTH(B13)<=9),"QUARTER 3",IF(AND(MONTH(B13)>=10,MONTH(B13)<=12),"QUARTER 4")))) -> QUARTER 1 | E13: =(C13-B13) -> 20 | F13: Asia | G13: Japan | H13: Osaka | I13: Corporate | J13: Distributor | K13: F. Müller | L13: Phones | N13: PHN-7019 | O13: 908.6 | P13: 691.37 | Q13: 0.25 | R13: 20
... A422: ORD-2023-623293 | B422: 45211 | C422: 45228 | D422: =IF(AND(MONTH(B422)>=1,MONTH(B422)<=3),"QUARTER 1",IF(AND(MONTH(B422)>=4,MONTH(B422)<=6),"QUARTER 2",IF(AND(MONTH(B422)>=7,MONTH(B422)<=9),"QUARTER 3",IF(AND(MONTH(B422)>=10,MONTH(B422)<=12),"QUARTER 4")))) -> QUARTER 4 | E422: =(C422-B422) -> 17 | F422: Asia | G422: Japan | H422: Nagoya | I422: Non-Profit | J422: Direct | K422: H. Kim | L422: Phones | N422: PHN-8478 | O422: 1102.19 | P422: 1711.16 | Q422: 0.151 | R422: 10
A423: ORD-2025-276968 | B423: 45713 | C423: 45733 | D423: =IF(AND(MONTH(B423)>=1,MONTH(B423)<=3),"QUARTER 1",IF(AND(MONTH(B423)>=4,MONTH(B423)<=6),"QUARTER 2",IF(AND(MONTH(B423)>=7,MONTH(B423)<=9),"QUARTER 3",IF(AND(MONTH(B423)>=10,MONTH(B423)<=12),"QUARTER 4")))) -> QUARTER 1 | E423: =C423-B423 -> 20 | F423: Americas | G423: USA | H423: San Francisco | I423: Non-Profit | J423: Marketplace | K423: H. Kim | L423: Phones | N423: PHN-1044 | O423: 1205.26 | P423: 1696.35 | Q423: 0.019 | R423: 6
A424: ORD-2025-650841 | B424: 45841 | C424: 45844 | D424: =IF(AND(MONTH(B424)>=1,MONTH(B424)<=3),"QUARTER 1",IF(AND(MONTH(B424)>=4,MONTH(B424)<=6),"QUARTER 2",IF(AND(MONTH(B424)>=7,MONTH(B424)<=9),"QUARTER 3",IF(AND(MONTH(B424)>=10,MONTH(B424)<=12),"QUARTER 4")))) -> QUARTER 3 | E424: =C424-B424 -> 3 | F424: Africa | G424: Nigeria | H424: Lagos | I424: Consumer | J424: Online | K424: A. Patel | L424: Laptops | N424: LAP-8910 | O424: 1313.3 | P424: 2884.34 | Q424: 0.157 | R424: 42
A425: ORD-2025-831576 | B425: 45915 | C425: 45925 | D425: =IF(AND(MONTH(B425)>=1,MONTH(B425)<=3),"QUARTER 1",IF(AND(MONTH(B425)>=4,MONTH(B425)<=6),"QUARTER 2",IF(AND(MONTH(B425)>=7,MONTH(B425)<=9),"QUARTER 3",IF(AND(MONTH(B425)>=10,MONTH(B425)<=12),"QUARTER 4")))) -> QUARTER 3 | E425: =C425-B425 -> 10 | F425: Asia | G425: India | H425: Delhi | I425: Consumer | J425: Retail | K425: A. Patel | L425: Phones | N425: PHN-2859 | O425: 1488.91 | P425: 1483.74 | Q425: 0.168 | R425: 24
A426: ORD-2024-468655 | B426: 45341 | C426: 45357 | D426: =IF(AND(MONTH(B426)>=1,MONTH(B426)<=3),"QUARTER 1",IF(AND(MONTH(B426)>=4,MONTH(B426)<=6),"QUARTER 2",IF(AND(MONTH(B426)>=7,MONTH(B426)<=9),"QUARTER 3",IF(AND(MONTH(B426)>=10,MONTH(B426)<=12),"QUARTER 4")))) -> QUARTER 1 | E426: =C426-B426 -> 16 | F426: Asia | G426: China | H426: Beijing | I426: Education | J426: Marketplace | K426: O. Wang | L426: Printers | N426: PRN-6308 | O426: 1477.84 | P426: 3197.47 | Q426: 0.243 | R426: 24
A427: ORD-2024-515105 | B427: 45349 | C427: 45377 | D427: =IF(AND(MONTH(B427)>=1,MONTH(B427)<=3),"QUARTER 1",IF(AND(MONTH(B427)>=4,MONTH(B427)<=6),"QUARTER 2",IF(AND(MONTH(B427)>=7,MONTH(B427)<=9),"QUARTER 3",IF(AND(MONTH(B427)>=10,MONTH(B427)<=12),"QUARTER 4")))) -> QUARTER 1 | E427: =C427-B427 -> 28 | F427: Asia | G427: India | H427: Mumbai | I427: Education | J427: Marketplace | K427: G. Dubois | L427: Laptops | N427: LAP-8469 | O427: 1035.19 | P427: 2322.7 | Q427: 0.173 | R427: 8
A428: ORD-2025-803803 | B428: 45897 | C428: 45905 | D428: =IF(AND(MONTH(B428)>=1,MONTH(B428)<=3),"QUARTER 1",IF(AND(MONTH(B428)>=4,MONTH(B428)<=6),"QUARTER 2",IF(AND(MONTH(B428)>=7,MONTH(B428)<=9),"QUARTER 3",IF(AND(MONTH(B428)>=10,MONTH(B428)<=12),"QUARTER 4")))) -> QUARTER 3 | E428: =C428-B428 -> 8 | F428: Africa | G428: Nigeria | H428: Port Harcourt | I428: Small Business | J428: Marketplace | K428: E. Garcia | L428: Laptops | N428: LAP-7553 | O428: 1271.1 | P428: 1932.42 | Q428: 0.25 | R428: 21
A429: ORD-2024-993481 | B429: 45522 | C429: 45547 | D429: =IF(AND(MONTH(B429)>=1,MONTH(B429)<=3),"QUARTER 1",IF(AND(MONTH(B429)>=4,MONTH(B429)<=6),"QUARTER 2",IF(AND(MONTH(B429)>=7,MONTH(B429)<=9),"QUARTER 3",IF(AND(MONTH(B429)>=10,MONTH(B429)<=12),"QUARTER 4")))) -> QUARTER 3 | E429: =C429-B429 -> 25 | F429: Asia | G429: India | H429: Mumbai | I429: Consumer | J429: Marketplace | K429: C. Otieno | L429: Phones | N429: PHN-3077 | O429: 1154.03 | P429: 1590.36 | Q429: 0.314 | R429: 18
A430: ORD-2024-811752 | B430: 45347 | C430: 45360 | D430: =IF(AND(MONTH(B430)>=1,MONTH(B430)<=3),"QUARTER 1",IF(AND(MONTH(B430)>=4,MONTH(B430)<=6),"QUARTER 2",IF(AND(MONTH(B430)>=7,MONTH(B430)<=9),"QUARTER 3",IF(AND(MONTH(B430)>=10,MONTH(B430)<=12),"QUARTER 4")))) -> QUARTER 1 | E430: =C430-B430 -> 13 | F430: Europe | G430: France | H430: Marseille | I430: Small Business | J430: Distributor | K430: E. Garcia | L430: Monitors | N430: MON-3350 | O430: 322.44 | P430: 395.61 | Q430: 0 | R430: 34
A431: ORD-2025-673091 | B431: 45784 | C431: 45790 | D431: =IF(AND(MONTH(B431)>=1,MONTH(B431)<=3),"QUARTER 1",IF(AND(MONTH(B431)>=4,MONTH(B431)<=6),"QUARTER 2",IF(AND(MONTH(B431)>=7,MONTH(B431)<=9),"QUARTER 3",IF(AND(MONTH(B431)>=10,MONTH(B431)<=12),"QUARTER 4")))) -> QUARTER 2 | E431: =C431-B431 -> 6 | F431: Asia | G431: India | H431: Bengaluru | I431: Enterprise | J431: Direct | K431: J. Njeri | L431: Phones | N431: PHN-5683 | O431: 935.98 | P431: 2077.69 | Q431: 0.175 | R431: 24
A432: ORD-2024-381197 | B432: 45597 | C432: 45608 | D432: =IF(AND(MONTH(B432)>=1,MONTH(B432)<=3),"QUARTER 1",IF(AND(MONTH(B432)>=4,MONTH(B432)<=6),"QUARTER 2",IF(AND(MONTH(B432)>=7,MONTH(B432)<=9),"QUARTER 3",IF(AND(MONTH(B432)>=10,MONTH(B432)<=12),"QUARTER 4")))) -> QUARTER 4 | E432: =C432-B432 -> 11 | F432: Europe | G432: Germany | H432: Frankfurt | I432: Consumer | J432: Online | K432: B. Chen | L432: Printers | N432: PRN-2409 | O432: 599.84 | P432: 1330.85 | Q432: 0.115 | R432: 11
A433: ORD-2024-651852 | B433: 45654 | C433: 45665 | D433: =IF(AND(MONTH(B433)>=1,MONTH(B433)<=3),"QUARTER 1",IF(AND(MONTH(B433)>=4,MONTH(B433)<=6),"QUARTER 2",IF(AND(MONTH(B433)>=7,MONTH(B433)<=9),"QUARTER 3",IF(AND(MONTH(B433)>=10,MONTH(B433)<=12),"QUARTER 4")))) -> QUARTER 4 | E433: =C433-B433 -> 11 | F433: Asia | G433: China | H433: Shenzhen | I433: Enterprise | J433: Online | K433: K. Singh | L433: Laptops | N433: LAP-8825 | O433: 1201.31 | P433: 2764.65 | Q433: 0 | R433: 21
A434: ORD-2023-659070 | B434: 45220 | C434: 45220 | D434: =IF(AND(MONTH(B434)>=1,MONTH(B434)<=3),"QUARTER 1",IF(AND(MONTH(B434)>=4,MONTH(B434)<=6),"QUARTER 2",IF(AND(MONTH(B434)>=7,MONTH(B434)<=9),"QUARTER 3",IF(AND(MONTH(B434)>=10,MONTH(B434)<=12),"QUARTER 4")))) -> QUARTER 4 | E434: =C434-B434 -> 0 | F434: Europe | G434: United Kingdom | H434: Manchester | I434: Enterprise | J434: Distributor | K434: J. Njeri | L434: Monitors | N434: MON-8697 | O434: 384.19 | P434: 278.35 | Q434: 0.056 | R434: 10
... A633: ORD-2025-728935 | B633: 45716 | C633: 45726 | D633: =IF(AND(MONTH(B633)>=1,MONTH(B633)<=3),"QUARTER 1",IF(AND(MONTH(B633)>=4,MONTH(B633)<=6),"QUARTER 2",IF(AND(MONTH(B633)>=7,MONTH(B633)<=9),"QUARTER 3",IF(AND(MONTH(B633)>=10,MONTH(B633)<=12),"QUARTER 4")))) -> QUARTER 1 | E633: =C633-B633 -> 10 | F633: Asia | G633: Japan | H633: Osaka | I633: Education | J633: Distributor | K633: N. Brown | L633: Laptops | N633: LAP-3017 | O633: 51.86 | P633: 45.98 | Q633: 0.173 | R633: 7
E635: =AVERAGE(E2:E633) -> 14.428797

Sheet DASHBOARD
A1: SALES DASHBOARD
A4: TOTAL REVENUE= 11004720 | F4: MARGIN%=28% | J4: GROSS PROFIT=5502 | O4: LEAD TIME DAY--14

Sheet LEAD TIME
A3: Count of Lead time date | B3: Column Labels
A4: Row Labels | B4: Accessories | C4: Components | D4: Laptops | E4: Monitors | F4: Networking | G4: Phones | H4: Printers | I4: Grand Total
A5: Brazil | B5: 10 | C5: 7 | D5: 5 | E5: 12 | F5: 12 | G5: 9 | H5: 7 | I5: 62
A6: Canada | B6: 6 | C6: 6 | D6: 6 | E6: 7 | F6: 3 | G6: 3 | H6: 13 | I6: 44
A7: China | B7: 4 | C7: 10 | D7: 5 | E7: 6 | F7: 8 | G7: 7 | H7: 11 | I7: 51
A8: France | B8: 7 | C8: 10 | D8: 6 | E8: 10 | F8: 6 | G8: 3 | H8: 12 | I8: 54
A9: Germany | B9: 9 | C9: 6 | D9: 7 | E9: 10 | F9: 4 | G9: 7 | H9: 8 | I9: 51
A10: India | B10: 8 | C10: 10 | D10: 9 | E10: 12 | F10: 7 | G10: 9 | H10: 6 | I10: 61
A11: Japan | B11: 5 | C11: 8 | D11: 7 | E11: 7 | F11: 12 | G11: 11 | H11: 9 | I11: 59
A12: Kenya | B12: 10 | C12: 5 | D12: 10 | E12: 2 | F12: 6 | G12: 15 | H12: 8 | I12: 56
A13: Nigeria | B13: 13 | C13: 6 | D13: 6 | E13: 5 | F13: 2 | G13: 6 | H13: 6 | I13: 44
A14: South Africa | B14: 4 | C14: 11 | D14: 7 | E14: 7 | F14: 7 | G14: 4 | H14: 5 | I14: 45
A15: United Kingdom | B15: 8 | C15: 7 | D15: 9 | E15: 7 | F15: 9 | G15: 4 | H15: 10 | I15: 54
A16: USA | B16: 4 | C16: 5 | D16: 5 | E16: 9 | F16: 10 | G16: 10 | H16: 8 | I16: 51
A17: Grand Total | B17: 88 | C17: 91 | D17: 82 | E17: 94 | F17: 86 | G17: 88 | H17: 103 | I17: 632
I25: TIME

Sheet Sheet1
A3: Row Labels | B3: Average of Gross Revenue
A4: <1/2/2023
A5: Qtr1 | B5: 15202.471
A6: Qtr2 | B6: 17804.896
A7: Qtr3 | B7: 19148.941
A8: Qtr4 | B8: 17455.111
A9: Grand Total | B9: 17412.532
C37: Row Labels | D37: Sum of DiscountPct | E37: Sum of Gross Revenue
C38: Accessories | D38: 0.115 | E38: 61681.167
C39: Components | D39: 0.355 | E39: 70763.335
C40: Laptops | D40: 0.112 | E40: 50496.03
C41: Monitors | D41: 0.178 | E41: 17600.579
C42: Networking | D42: 0.131 | E42: 14912.04
C43: Phones | D43: 0.505 | E43: 50963.032
C44: Printers | D44: 0.642 | E44: 77137.045
C45: Grand Total | D45: 2.038 | E45: 343553.23

Sheet SALESPERSON 
A1: ProductCategory | B1: All
A3: Average of Gross Revenue | B3: Column Labels
B4: 2023 | C4: 2024 | D4: 2025 | E4: Grand Total
A7: Row Labels
A8: A. Patel | B8: 19952.536 | C8: 14686.919 | D8: 31385.549 | E8: 20835.797
A9: B. Chen | B9: 16703.327 | C9: 21126.248 | D9: 17011.522 | E9: 18500.103
A10: C. Otieno | B10: 20562.138 | C10: 22026.334 | D10: 12790.671 | E10: 18516.537
A11: D. Smith | B11: 15955.689 | C11: 17075.389 | D11: 8940.8497 | E11: 15134.934
A12: E. Garcia | B12: 16099.846 | C12: 16029.107 | D12: 15780.098 | E12: 15995.484
A13: F. Müller | B13: 9885.505 | C13: 19108.94 | D13: 18898.315 | E13: 16387.576
A14: G. Dubois | B14: 15497.752 | C14: 22838.391 | D14: 12516.889 | E14: 17614.516
A15: H. Kim | B15: 13043.485 | C15: 15561.27 | D15: 20902.758 | E15: 16900.958
A16: I. Johnson | B16: 13552.367 | C16: 14293.252 | D16: 16055.302 | E16: 14460.104
A17: J. Njeri | B17: 15028.032 | C17: 16158.034 | D17: 18820.905 | E17: 16244.927
A18: K. Singh | B18: 22401.647 | C18: 18414.398 | D18: 19165.674 | E18: 20015.732
A19: L. Okafor | B19: 17554.564 | C19: 22063.059 | D19: 15262.818 | E19: 18310.798
... A23: Grand Total | B23: 16381.935 | C23: 18763.572 | D23: 16884.956 | E23: 17412.532

Sheet Sheet3

Sheet Calculations
A1: Order ID | B1: Order Date | C1: Required Date | D1: Quarter 1 | E1: Salesperson | F1: ProductCategory | G1: SKU | H1: UnitCost | I1: UnitPrice | J1: DiscountPct | K1: Quantity | L1: Gross Revenue | M1: Cost of Goods | N1: Gross profit | O1: Margin pct
A2: ORD-2024-275203 | B2: 45362 | C2: 45388 | D2: =IF(AND(MONTH(B2)>=1,MONTH(B2)<=3),"QUARTER 1",IF(AND(MONTH(B2)>=4,MONTH(B2)<=6),"QUARTER 2",IF(AND(MONTH(B2)>=7,MONTH(B2)<=9),"QUARTER 3",IF(AND(MONTH(B2)>=10,MONTH(B2)<=12),"QUARTER 4")))) -> QUARTER 1 | E2: C. Otieno | F2: Components | G2: CMP-8270 | H2: 279.24 | I2: 608.9 | J2: 0.112 | K2: 9 | L2: =(Calculations!I2*Calculations!K2*(1-Calculations!J2)) -> 4866.3288 | M2: =(H2*K2) -> 2513.16 | N2: =(L2-Calculations!M2) -> 2353.1688 | O2: =(N2/L2)*100 -> 48.356141
A3: ORD-2024-358795 | B3: 45587 | C3: 45588 | D3: =IF(AND(MONTH(B3)>=1,MONTH(B3)<=3),"QUARTER 1",IF(AND(MONTH(B3)>=4,MONTH(B3)<=6),"QUARTER 2",IF(AND(MONTH(B3)>=7,MONTH(B3)<=9),"QUARTER 3",IF(AND(MONTH(B3)>=10,MONTH(B3)<=12),"QUARTER 4")))) -> QUARTER 4 | E3: J. Njeri | F3: Printers | G3: PRN-9322 | H3: 1084.39 | I3: 759.33 | J3: 0.237 | K3: 31 | L3: =(Calculations!I3*Calculations!K3*(1-Calculations!J3)) -> 17960.432 | M3: =(H3*K3) -> 33616.09 | N3: =(L3-Calculations!M3) -> -15655.658 | O3: =(N3/L3)*100 -> -87.167486
A4: ORD-2023-373538 | B4: 44985 | C4: 45010 | D4: =IF(AND(MONTH(B4)>=1,MONTH(B4)<=3),"QUARTER 1",IF(AND(MONTH(B4)>=4,MONTH(B4)<=6),"QUARTER 2",IF(AND(MONTH(B4)>=7,MONTH(B4)<=9),"QUARTER 3",IF(AND(MONTH(B4)>=10,MONTH(B4)<=12),"QUARTER 4")))) -> QUARTER 1 | E4: I. Johnson | F4: Networking | G4: NET-9666 | H4: 1460.76 | I4: 1430 | J4: 0.131 | K4: 12 | L4: =(Calculations!I4*Calculations!K4*(1-Calculations!J4)) -> 14912.04 | M4: =(H4*K4) -> 17529.12 | N4: =(L4-Calculations!M4) -> -2617.08 | O4: =(N4/L4)*100 -> -17.550114
A5: ORD-2025-168148 | B5: 45745 | C5: 45749 | D5: =IF(AND(MONTH(B5)>=1,MONTH(B5)<=3),"QUARTER 1",IF(AND(MONTH(B5)>=4,MONTH(B5)<=6),"QUARTER 2",IF(AND(MONTH(B5)>=7,MONTH(B5)<=9),"QUARTER 3",IF(AND(MONTH(B5)>=10,MONTH(B5)<=12),"QUARTER 4")))) -> QUARTER 1 | E5: G. Dubois | F5: Phones | G5: PHN-4556 | H5: 259.93 | I5: 255.94 | J5: 0.072 | K5: 22 | L5: =(Calculations!I5*Calculations!K5*(1-Calculations!J5)) -> 5225.271 | M5: =(H5*K5) -> 5718.46 | N5: =(L5-Calculations!M5) -> -493.18896 | O5: =(N5/L5)*100 -> -9.4385335
A6: ORD-2023-824839 | B6: 45266 | C6: 45291 | D6: =IF(AND(MONTH(B6)>=1,MONTH(B6)<=3),"QUARTER 1",IF(AND(MONTH(B6)>=4,MONTH(B6)<=6),"QUARTER 2",IF(AND(MONTH(B6)>=7,MONTH(B6)<=9),"QUARTER 3",IF(AND(MONTH(B6)>=10,MONTH(B6)<=12),"QUARTER 4")))) -> QUARTER 4 | E6: L. Okafor | F6: Printers | G6: PRN-8041 | H6: 663.03 | I6: 813.51 | J6: 0.102 | K6: 15 | L6: =(Calculations!I6*Calculations!K6*(1-Calculations!J6)) -> 10957.98 | M6: =(H6*K6) -> 9945.45 | N6: =(L6-Calculations!M6) -> 1012.5297 | O6: =(N6/L6)*100 -> 9.2401129
A7: ORD-2023-723587 | B7: 44928 | C7: 44931 | D7: =IF(AND(MONTH(B7)>=1,MONTH(B7)<=3),"QUARTER 1",IF(AND(MONTH(B7)>=4,MONTH(B7)<=6),"QUARTER 2",IF(AND(MONTH(B7)>=7,MONTH(B7)<=9),"QUARTER 3",IF(AND(MONTH(B7)>=10,MONTH(B7)<=12),"QUARTER 4")))) -> QUARTER 1 | E7: B. Chen | F7: Laptops | G7: Not Provided | H7: 315.87 | I7: 591.68 | J7: 0 | K7: 7 | L7: =(Calculations!I7*Calculations!K7*(1-Calculations!J7)) -> 4141.76 | M7: =(H7*K7) -> 2211.09 | N7: =(L7-Calculations!M7) -> 1930.67 | O7: =(N7/L7)*100 -> 46.614724
A8: ORD-2024-336584 | B8: 45653 | C8: 45671 | D8: =IF(AND(MONTH(B8)>=1,MONTH(B8)<=3),"QUARTER 1",IF(AND(MONTH(B8)>=4,MONTH(B8)<=6),"QUARTER 2",IF(AND(MONTH(B8)>=7,MONTH(B8)<=9),"QUARTER 3",IF(AND(MONTH(B8)>=10,MONTH(B8)<=12),"QUARTER 4")))) -> QUARTER 4 | E8: E. Garcia | F8: Monitors | G8: MON-8629 | H8: 586.07 | I8: 845.97 | J8: 0.147 | K8: 4 | L8: =(Calculations!I8*Calculations!K8*(1-Calculations!J8)) -> 2886.4496 | M8: =(H8*K8) -> 2344.28 | N8: =(L8-Calculations!M8) -> 542.16964 | O8: =(N8/L8)*100 -> 18.78327
A9: ORD-2023-112666 | B9: 44939 | C9: 44941 | D9: =IF(AND(MONTH(B9)>=1,MONTH(B9)<=3),"QUARTER 1",IF(AND(MONTH(B9)>=4,MONTH(B9)<=6),"QUARTER 2",IF(AND(MONTH(B9)>=7,MONTH(B9)<=9),"QUARTER 3",IF(AND(MONTH(B9)>=10,MONTH(B9)<=12),"QUARTER 4")))) -> QUARTER 1 | E9: O. Wang | F9: Printers | G9: PRN-6276 | H9: 28.38 | I9: 47.22 | J9: 0.194 | K9: 18 | L9: =(Calculations!I9*Calculations!K9*(1-Calculations!J9)) -> 685.06776 | M9: =(H9*K9) -> 510.84 | N9: =(L9-Calculations!M9) -> 174.22776 | O9: =(N9/L9)*100 -> 25.432194
A10: ORD-2024-589570 | B10: 45416 | C10: 45441 | D10: =IF(AND(MONTH(B10)>=1,MONTH(B10)<=3),"QUARTER 1",IF(AND(MONTH(B10)>=4,MONTH(B10)<=6),"QUARTER 2",IF(AND(MONTH(B10)>=7,MONTH(B10)<=9),"QUARTER 3",IF(AND(MONTH(B10)>=10,MONTH(B10)<=12),"QUARTER 4")))) -> QUARTER 2 | E10: O. Wang | F10: Monitors | G10: MON-6892 | H10: 1295.34 | I10: 2530.81 | J10: 0.031 | K10: 6 | L10: =(Calculations!I10*Calculations!K10*(1-Calculations!J10)) -> 14714.129 | M10: =(H10*K10) -> 7772.04 | N10: =(L10-Calculations!M10) -> 6942.0893 | O10: =(N10/L10)*100 -> 47.179749
A11: ORD-2025-997421 | B11: 45798 | C11: 45817 | D11: =IF(AND(MONTH(B11)>=1,MONTH(B11)<=3),"QUARTER 1",IF(AND(MONTH(B11)>=4,MONTH(B11)<=6),"QUARTER 2",IF(AND(MONTH(B11)>=7,MONTH(B11)<=9),"QUARTER 3",IF(AND(MONTH(B11)>=10,MONTH(B11)<=12),"QUARTER 4")))) -> QUARTER 2 | E11: A. Patel | F11: Components | G11: CMP-3731 | H11: 1331.38 | I11: 2309.56 | J11: 0.149 | K11: 31 | L11: =(Calculations!I11*Calculations!K11*(1-Calculations!J11)) -> 60928.502 | M11: =(H11*K11) -> 41272.78 | N11: =(L11-Calculations!M11) -> 19655.722 | O11: =(N11/L11)*100 -> 32.260308
A12: ORD-2024-210687 | B12: 45319 | C12: 45331 | D12: =IF(AND(MONTH(B12)>=1,MONTH(B12)<=3),"QUARTER 1",IF(AND(MONTH(B12)>=4,MONTH(B12)<=6),"QUARTER 2",IF(AND(MONTH(B12)>=7,MONTH(B12)<=9),"QUARTER 3",IF(AND(MONTH(B12)>=10,MONTH(B12)<=12),"QUARTER 4")))) -> QUARTER 1 | E12: G. Dubois | F12: Accessories | G12: ACC-7938 | H12: 644.17 | I12: 700.12 | J12: 0.006 | K12: 23 | L12: =(Calculations!I12*Calculations!K12*(1-Calculations!J12)) -> 16006.143 | M12: =(H12*K12) -> 14815.91 | N12: =(L12-Calculations!M12) -> 1190.2334 | O12: =(N12/L12)*100 -> 7.4361038
A13: ORD-2025-515515 | B13: 45660 | C13: 45680 | D13: =IF(AND(MONTH(B13)>=1,MONTH(B13)<=3),"QUARTER 1",IF(AND(MONTH(B13)>=4,MONTH(B13)<=6),"QUARTER 2",IF(AND(MONTH(B13)>=7,MONTH(B13)<=9),"QUARTER 3",IF(AND(MONTH(B13)>=10,MONTH(B13)<=12),"QUARTER 4")))) -> QUARTER 1 | E13: F. Müller | F13: Phones | G13: PHN-7019 | H13: 908.6 | I13: 691.37 | J13: 0.25 | K13: 20 | L13: =(Calculations!I13*Calculations!K13*(1-Calculations!J13)) -> 10370.55 | M13: =(H13*K13) -> 18172 | N13: =(L13-Calculations!M13) -> -7801.45 | O13: =(N13/L13)*100 -> -75.226965
... A633: ORD-2025-728935 | B633: 45716 | C633: 45726 | D633: =IF(AND(MONTH(B633)>=1,MONTH(B633)<=3),"QUARTER 1",IF(AND(MONTH(B633)>=4,MONTH(B633)<=6),"QUARTER 2",IF(AND(MONTH(B633)>=7,MONTH(B633)<=9),"QUARTER 3",IF(AND(MONTH(B633)>=10,MONTH(B633)<=12),"QUARTER 4")))) -> QUARTER 1 | E633: N. Brown | F633: Laptops | G633: LAP-3017 | H633: 51.86 | I633: 45.98 | J633: 0.173 | K633: 7 | L633: =(Calculations!I633*Calculations!K633*(1-Calculations!J633)) -> 266.17822 | M633: =(H633*K633) -> 363.02 | N633: =(L633-Calculations!M633) -> -96.84178 | O633: =(N633/L633)*100 -> -36.382308
L635: =-SUM(L2:L633) -> -11004720 | N635: =AVERAGE(N2:N633) -> 5501.5387 | O635: =AVERAGE(O2:O633) -> 28.384388

Sheet ABC ANALYSIS
B3: Column Labels
B4: Average of Gross Revenue | F4: Count of SKU | J4: Total Average of Gross Revenue | K4: Total Count of SKU
A5: Row Labels | B5: Africa | C5: Americas | D5: Asia | E5: Europe | F5: Africa | G5: Americas | H5: Asia | I5: Europe
A6: Accessories | B6: 15847.997 | C6: 15847.997 | D6: 15847.997 | E6: 15847.997 | F6: 88 | G6: 88 | H6: 88 | I6: 88 | J6: 15847.997 | K6: 88
A7: Components | B7: 16985.132 | C7: 16985.132 | D7: 16985.132 | E7: 16985.132 | F7: 91 | G7: 91 | H7: 91 | I7: 91 | J7: 16985.132 | K7: 91
A8: Laptops | B8: 20867.005 | C8: 20867.005 | D8: 20867.005 | E8: 20867.005 | F8: 82 | G8: 82 | H8: 82 | I8: 82 | J8: 20867.005 | K8: 82
A9: Monitors | B9: 16483.617 | C9: 16483.617 | D9: 16483.617 | E9: 16483.617 | F9: 94 | G9: 94 | H9: 94 | I9: 94 | J9: 16483.617 | K9: 94
A10: Networking | B10: 20801.755 | C10: 20801.755 | D10: 20801.755 | E10: 20801.755 | F10: 86 | G10: 86 | H10: 86 | I10: 86 | J10: 20801.755 | K10: 86
A11: Phones | B11: 15895.926 | C11: 15895.926 | D11: 15895.926 | E11: 15895.926 | F11: 88 | G11: 88 | H11: 88 | I11: 88 | J11: 15895.926 | K11: 88
A12: Printers | B12: 15690.317 | C12: 15690.317 | D12: 15690.317 | E12: 15690.317 | F12: 103 | G12: 103 | H12: 103 | I12: 103 | J12: 15690.317 | K12: 103
A13: Grand Total | B13: 17412.532 | C13: 17412.532 | D13: 17412.532 | E13: 17412.532 | F13: 632 | G13: 632 | H13: 632 | I13: 632 | J13: 17412.532 | K13: 632

Sheet CHANEL 
A1: ProductCategory | B1: All
A3: Sum of Gross profit | B3: Column Labels
A4: Row Labels | B4: Africa | C4: Americas | D4: Asia | E4: Europe | F4: Grand Total
A5: Direct | B5: 592902.73 | C5: 592902.73 | D5: 592902.73 | E5: 592902.73 | F5: 592902.73
A6: Distributor | B6: 592902.73 | C6: 592902.73 | D6: 592902.73 | E6: 592902.73 | F6: 592902.73
A7: Marketplace | B7: 592902.73 | C7: 592902.73 | D7: 592902.73 | E7: 592902.73 | F7: 592902.73
A8: Online | B8: 592902.73 | C8: 592902.73 | D8: 592902.73 | E8: 592902.73 | F8: 592902.73
A9: Retail | B9: 592902.73 | C9: 592902.73 | D9: 592902.73 | E9: 592902.73 | F9: 592902.73
A10: Grand Total | B10: 592902.73 | C10: 592902.73 | D10: 592902.73 | E10: 592902.73 | F10: 592902.73

Sheet WHAT IF
A1: Gross Revenue | B1: Gross profit | C1: GLOBAL DISCOUNT | D1: UNIT COST INFLATION | E1: QUANTITY UPLIFT
A2: 4866.3288 | B2: 2353.1688 | C2: =IF(A2*25%,B2*25%) -> 588.2922 | D2: =IF(A2*15%,B2*15%) -> 352.97532 | E2: =IF(A2*20%,B2*20%) -> 470.63376
A3: 17960.432 | B3: -15655.658 | C3: =IF(A3*25%,B3*25%) -> -3913.9144 | D3: =IF(A3*15%,B3*15%) -> -2348.3486 | E3: =IF(A3*20%,B3*20%) -> -3131.1315
A4: 14912.04 | B4: -2617.08 | C4: =IF(A4*25%,B4*25%) -> -654.27 | D4: =IF(A4*15%,B4*15%) -> -392.562 | E4: =IF(A4*20%,B4*20%) -> -523.416
A5: 5225.271 | B5: -493.18896 | C5: =IF(A5*25%,B5*25%) -> -123.29724 | D5: =IF(A5*15%,B5*15%) -> -73.978344 | E5: =IF(A5*20%,B5*20%) -> -98.637792
A6: 10957.98 | B6: 1012.5297 | C6: =IF(A6*25%,B6*25%) -> 253.13243 | D6: =IF(A6*15%,B6*15%) -> 151.87946 | E6: =IF(A6*20%,B6*20%) -> 202.50594
A7: 4141.76 | B7: 1930.67 | C7: =IF(A7*25%,B7*25%) -> 482.6675 | D7: =IF(A7*15%,B7*15%) -> 289.6005 | E7: =IF(A7*20%,B7*20%) -> 386.134
A8: 2886.4496 | B8: 542.16964 | C8: =IF(A8*25%,B8*25%) -> 135.54241 | D8: =IF(A8*15%,B8*15%) -> 81.325446 | E8: =IF(A8*20%,B8*20%) -> 108.43393
A9: 685.06776 | B9: 174.22776 | C9: =IF(A9*25%,B9*25%) -> 43.55694 | D9: =IF(A9*15%,B9*15%) -> 26.134164 | E9: =IF(A9*20%,B9*20%) -> 34.845552
A10: 14714.129 | B10: 6942.0893 | C10: =IF(A10*25%,B10*25%) -> 1735.5223 | D10: =IF(A10*15%,B10*15%) -> 1041.3134 | E10: =IF(A10*20%,B10*20%) -> 1388.4179
A11: 60928.502 | B11: 19655.722 | C11: =IF(A11*25%,B11*25%) -> 4913.9306 | D11: =IF(A11*15%,B11*15%) -> 2948.3584 | E11: =IF(A11*20%,B11*20%) -> 3931.1445
A12: 16006.143 | B12: 1190.2334 | C12: =IF(A12*25%,B12*25%) -> 297.55836 | D12: =IF(A12*15%,B12*15%) -> 178.53502 | E12: =IF(A12*20%,B12*20%) -> 238.04669
A13: 10370.55 | B13: -7801.45 | C13: =IF(A13*25%,B13*25%) -> -1950.3625 | D13: =IF(A13*15%,B13*15%) -> -1170.2175 | E13: =IF(A13*20%,B13*20%) -> -1560.29
... A633: 266.17822 | B633: -96.84178 | C633: =IF(A633*25%,B633*25%) -> -24.210445 | D633: =IF(A633*15%,B633*15%) -> -14.526267 | E633: =IF(A633*20%,B633*20%) -> -19.368356

Sheet IN
A1: INSIGHTS
A2: AFRICA
A3: AMERICA
A4: ASIA
A5: EUROPE-
